Workbook

Sheet Ref_Tolerance
A1: FACILITY_TYPE | B1: TOLERANCE_PCT | C1: BASIS | D1: METRIC_TYPE | E1: DAFMAN_CITE | F1: TIER | G1: NOTES
A2: DFAC_LEGACY | B2: 0.03 | C2: MONTHLY_EARNED_INCOME | D2: VARIANCE | E2: 5.13 | F2: T-2 | G2: Para 5.13 sets 3% for DFAC food accounts; para 6.6 sets 5% for CAFE facilities. Both T-2. Applied standard depends on facility classification. Inconsistency surfaced intentionally.
A3: CAFE | B3: 0.05 | C3: TOTAL_EARNED_INCOME | D3: VARIANCE | E3: 6.6 | F3: T-2 | G3: Para 5.13 sets 3% for DFAC food accounts; para 6.6 sets 5% for CAFE facilities. Both T-2. Applied standard depends on facility classification. Inconsistency surfaced intentionally.
A4: FOOD_2_0 | B4: 0.45 | C4: COST_OF_GOODS | D4: MARGIN | E4: 6.6, 3.13.3 | F4: T-2 | G4: 45% COG is a pricing/margin standard, not a variance tolerance. Food 2.0 sites have no AvT-equivalent variance control. A site can meet 45% COG exactly and still carry large theoretical-vs-actual variance.
A5: ANG_DFAC | B5: 0.1 | C5: TOTAL_EARNED_INCOME | D5: VARIANCE | E5: 6.6 | F5: T-2
A6: FIELD_FEEDING | B6: 0.03 | C6: TOTAL_EARNED_INCOME | D6: VARIANCE | E6: 5.18.6 | F6: T-2
A7: NGB_UTA | B7: 0.1 | C7: MONTHLY_EARNED_INCOME | D7: VARIANCE | E7: 5.13.1 | F7: T-2
A8: NGB_AT | B8: 0.05 | C8: MONTHLY_EARNED_INCOME | D8: VARIANCE | E8: 5.13.1 | F8: T-2
A9: NGB_EXTENDED | B9: 0.03 | C9: MONTHLY_EARNED_INCOME | D9: VARIANCE | E9: 5.13.1 | F9: T-2
A11: REGULATORY TABLE — DO NOT EDIT TOLERANCE VALUES.
A12: Tolerances are set by DAFMAN 34-131. To change how a facility is scored, change its FACILITY_TYPE in Ref_Crosswalk, not a value here.
A13: TOLERANCE_PCT is stored as a fraction (0.03 renders 3.0%). METRIC_TYPE MARGIN (Food 2.0) is tested on cost-of-goods, not variance.

Sheet Ref_Calendar
A1: PERIOD_KEY | B1: FY | C1: MONTH | D1: HALF | E1: START_DATE | F1: END_DATE | G1: INVENTORY_DUE | H1: POST_DUE | I1: MMR_DUE | J1: STATUS
A2: FY2025-P10A | B2: 2025 | C2: 10 | D2: A | E2: 45566 | F2: 45580 | G2: 45580 | H2: 45585 | I2: 45606 | J2: CLOSED
A3: FY2025-P10B | B3: 2025 | C3: 10 | D3: B | E3: 45581 | F3: 45596 | G3: 45596 | H3: 45601 | I3: 45606 | J3: CLOSED
A4: FY2025-P11A | B4: 2025 | C4: 11 | D4: A | E4: 45597 | F4: 45611 | G4: 45611 | H4: 45616 | I4: 45636 | J4: CLOSED
A5: FY2025-P11B | B5: 2025 | C5: 11 | D5: B | E5: 45612 | F5: 45626 | G5: 45626 | H5: 45631 | I5: 45636 | J5: CLOSED
A6: FY2025-P12A | B6: 2025 | C6: 12 | D6: A | E6: 45627 | F6: 45641 | G6: 45641 | H6: 45646 | I6: 45667 | J6: CLOSED
A7: FY2025-P12B | B7: 2025 | C7: 12 | D7: B | E7: 45642 | F7: 45657 | G7: 45657 | H7: 45662 | I7: 45667 | J7: CLOSED
A8: FY2025-P01A | B8: 2025 | C8: 1 | D8: A | E8: 45658 | F8: 45672 | G8: 45672 | H8: 45677 | I8: 45698 | J8: CLOSED
A9: FY2025-P01B | B9: 2025 | C9: 1 | D9: B | E9: 45673 | F9: 45688 | G9: 45688 | H9: 45693 | I9: 45698 | J9: CLOSED
A10: FY2025-P02A | B10: 2025 | C10: 2 | D10: A | E10: 45689 | F10: 45703 | G10: 45703 | H10: 45708 | I10: 45726 | J10: CLOSED
A11: FY2025-P02B | B11: 2025 | C11: 2 | D11: B | E11: 45704 | F11: 45716 | G11: 45716 | H11: 45721 | I11: 45726 | J11: CLOSED
A12: FY2025-P03A | B12: 2025 | C12: 3 | D12: A | E12: 45717 | F12: 45731 | G12: 45731 | H12: 45736 | I12: 45757 | J12: CLOSED
A13: FY2025-P03B | B13: 2025 | C13: 3 | D13: B | E13: 45732 | F13: 45747 | G13: 45747 | H13: 45752 | I13: 45757 | J13: CLOSED
... A97: FY2028-P09B | B97: 2028 | C97: 9 | D97: B | E97: 47012 | F97: 47026 | G97: 47026 | H97: 47031 | I97: 47036 | J97: OPEN
A99: Semi-monthly periods (para 7.13 inventory on 15th & last day; para 5.2.5 MMR due 10th of following month). STATUS is maintained by the build owner.

Sheet Ref_Crosswalk
A1: DFAC_ID | B1: DFAC_NAME | C1: BASE_ID | D1: BASE_NAME | E1: MAJCOM | F1: FACILITY_TYPE | G1: DODAAC | H1: ALOHA_STORE | I1: CT_SITE | J1: CIR_MERCHANT | K1: STORES_ACCT | L1: ACTIVE | M1: EFF_START | N1: EFF_END | O1: NOTES
A2: JBSA-01 | B2: Gateway Inn | C2: JBSA | D2: Joint Base San Antonio | E2: AETC | F2: DFAC_LEGACY | G2: FA1234 | L2: Y | M2: 45931 | O2: Example row — replace with real DFACs | P2: ◄ EXAMPLE
A202: LEGEND
A203: Yellow cells = fill these in. Placeholder columns (ALOHA_STORE, CT_SITE, CIR_MERCHANT, STORES_ACCT) await real system identifiers — leave blank until you have real exports.
A204: DFAC_ID is the canonical key, format {BASE_ID}-{NN} (e.g. JBSA-01). Once assigned, never change one — retire via EFF_END and reissue. FACILITY_TYPE must match Ref_Tolerance exactly.

Sheet Ref_ExceptionTypes
A1: EXC_CODE | B1: EXC_NAME | C1: CATEGORY | D1: DEFAULT_OWNER | E1: REMEDIATION
A2: LINK_ERR | B2: Item linked incorrectly | C2: CT_VS_ALOHA | D2: AFSVC/VMF | E2: Route to VMF — bases cannot self-correct links (para 7.8.1)
A3: PRICE_ERR | B3: Incorrect POS price | C3: CT_VS_ALOHA | D3: AFSVC/VMF | E3: Pricing centrally managed (para 3.13.1, 6.4)
A4: VOID_ERR | B4: Void not propagated | C4: CT_VS_ALOHA | D4: Base accountant | E4: Verify POS void handling
A5: ADJ_ERR | B5: Wrong inventory adjustment | C5: CT_VS_ALOHA | D5: Base DFAC manager | E5: Review raw/finished waste entries (para 7.10)
A6: PURCH_VAR | B6: Purchase vs SF 1080 mismatch | C6: PURCHASES | D6: Base accountant | E6: Purchase Reconciliation Worksheet (para 7.18)
A7: MISSING_SRC | B7: Expected source file absent | C7: INGEST | D7: Base accountant | E7: Check export/upload
A8: PROV_NULL | B8: Provenance incomplete | C8: INTEGRITY | D8: Build owner | E8: Adapter defect — fix immediately
A9: XWALK_UNRESOLVED | B9: DFAC_ID not in crosswalk | C9: INTEGRITY | D9: AFSVC/VMF | E9: Add to crosswalk registry
A10: TOL_BREACH | B10: Out of tolerance | C10: COMPLIANCE | D10: FSO/FSSC | E10: See escalation ladder (para 5.13.2)
A12: Seed taxonomy (spec §5.6). Referenced by the reconciliation layer in Stage 3; ownership routing enforced there.

Sheet Ref_AdapterManifest
A1: QUERY_NAME | B1: LAYER | C1: SOURCE_SYSTEM | D1: INPUT_PATH | E1: OUTPUT_TABLE | F1: ADAPTER_VER | G1: OWNER | H1: LAST_CHANGED | I1: STATUS | J1: TEST_FILE | K1: NOTES
A2: adapter_DFAS_SIK_v2 | B2: ADAPTER | C2: DFAS | D2: \ingest\dfas\ | E2: ledger_Transactions | F2: DFAS_v2 | G2: AFSVC/VMF | H2: 46235 | I2: STUB | J2: \tests\dfas_sample.pdf | K2: Example — adapters remain stubs until real headers arrive (§14) | M2: ◄ EXAMPLE
A41: Hand-maintained transformation graph. Register each Power Query here with a path to a known-good TEST_FILE. Adapters are Stage 2+; none are ACTIVE yet.

Sheet Ref_CrosswalkVersion
A1: CROSSWALK_VER | B1: EFFECTIVE_DATE | C1: CHANGED_BY | D1: CHANGE_SUMMARY | E1: ROW_COUNT
A2: CW-2026-08-01 | B2: 46235 | C2: AFSVC/VMF | D2: Initial registry | E2: 1 | G2: ◄ EXAMPLE
A31: Every crosswalk change gets a new version row. Ledger rows stamp the CROSSWALK_VER that resolved them, so silent mapping drift is detectable (Stage 2+).

Sheet Out_ComplianceTracker
A1: MISSION FEEDING — COMPLIANCE TRACKER
A2: One row per DFAC per period. Enter the yellow input columns; everything right of NOTES is computed. Then press Data > Refresh (F9).
A3: HOW TO USE:
A4: 1) Pick DFAC_ID and PERIOD_KEY (dropdowns). 2) Enter EARNED_INCOME and GAIN_LOSS_AMT from the Monthly Monetary Record. 3) COST_OF_GOODS for Food 2.0 sites only. 4) Mark MFR/FSS_CC/INVESTIGATION as those actions occur.
A5: Blue = you type it (yellow cells). Black = computed, do not edit. Red fill = act now. Amber fill = watch.
A6: Tolerance selection, pass/fail, streak counting and escalation are all computed. Do not hand-calculate any of it.
A7: DFAC_ID | B7: PERIOD_KEY | C7: EARNED_INCOME | D7: GAIN_LOSS_AMT | E7: COST_OF_GOODS | F7: MFR_SUBMITTED | G7: FSS_CC_SIGNED | H7: INVESTIGATION_OPENED | I7: NOTES | J7: FACILITY_TYPE | K7: TOLERANCE_PCT | L7: METRIC_TYPE | M7: VAR_PCT | N7: COG_PCT | O7: STREAK | P7: RESULT | Q7: DAFMAN_CITE | R7: ESCALATION | S7: WATCH | T7: ACTION_OVERDUE | U7: SEQ (helper) | V7: LASTPASS (helper) | W7: MAJCOM (helper) | X7: BASE_ID (helper) | Y7: MATCHF (helper) | Z7: WATCH_RANK (helper) | AA7: OVERDUE_RANK (helper)
A8: JBSA-01 | B8: FY2026-P07A | C8: 100000 | D8: 2500 | F8: Y | G8: Y | H8: N | I8: Example row — clean PASS (2.5% <= 3.0%) | J8: =IF($A8="","",IFERROR(INDEX('Ref_Crosswalk'!$F$2:$F$500,MATCH($A8,'Ref_Crosswalk'!$A$2:$A$500,0)),"UNKNOWN")) | K8: =IF($A8="","",IFERROR(INDEX('Ref_Tolerance'!$B$2:$B$9,MATCH($J8,'Ref_Tolerance'!$A$2:$A$9,0)),"")) | L8: =IF($A8="","",IFERROR(INDEX('Ref_Tolerance'!$D$2:$D$9,MATCH($J8,'Ref_Tolerance'!$A$2:$A$9,0)),"")) | M8: =IF($A8="","",IFERROR(ABS(N($D8))/N($C8),0)) | N8: =IF($A8="","",IFERROR(N($E8)/N($C8),0)) | O8: =IF($A8="",0,IFERROR(SUMPRODUCT(($A$8:$A$307=$A8)*($P$8:$P$307="FAIL")*($U$8:$U$307>$V8)*($U$8:$U$307<=$U8)),0)) | P8: =IF($A8="","",IFERROR(IF(NOT(ISNUMBER($K8)),"CHECK",IF($L8="MARGIN",IF($N8<=$K8,"PASS","FAIL"),IF($M8<=$K8,"PASS","FAIL"))),"CHECK")) | Q8: =IF($A8="","",IFERROR(INDEX('Ref_Tolerance'!$E$2:$E$9,MATCH($J8,'Ref_Tolerance'!$A$2:$A$9,0)),"")) | R8: =IF($A8="","",IFERROR(IF($O8=0,"CLEAR",IF($O8=1,"MFR DUE - MANAGER",IF($O8=2,"MFR DUE - FSS/CC SIGNATURE REQUIRED","INVESTIGATION + REPORT OF SURVEY; MSG/CC NOTIFIED"))),"")) | S8: =IF($A8="","",IF($O8=2,"WATCH - ONE MORE MISS TRIGGERS INVESTIGATION","")) | T8: =IF($A8="","",IFERROR(IF(AND($O8>=1,$F8<>"Y"),"MFR NOT SUBMITTED",IF(AND($O8>=2,$G8<>"Y"),"FSS/CC SIGNATURE MISSING",IF(AND($O8>=3,$H8<>"Y"),"INVESTIGATION NOT OPENED",""))),"")) | U8: =IF($A8="",0,IFERROR(MATCH($B8,'Ref_Calendar'!$A$2:$A$500,0),0)) | V8: =IF($A8="",0,IFERROR(SUMPRODUCT(MAX(($A$8:$A$307=$A8)*($P$8:$P$307="PASS")*($U$8:$U$307<=$U8)*$U$8:$U$307)),0)) | W8: =IF($A8="","",IFERROR(INDEX('Ref_Crosswalk'!$E$2:$E$500,MATCH($A8,'Ref_Crosswalk'!$A$2:$A$500,0)),"")) | X8: =IF($A8="","",IFERROR(INDEX('Ref_Crosswalk'!$C$2:$C$500,MATCH($A8,'Ref_Crosswalk'!$A$2:$A$500,0)),"")) | Y8: =IF($A8="",0,IF(AND(OR('Out_Dashboard'!$C$5="",$W8='Out_Dashboard'!$C$5),OR('Out_Dashboard'!$C$6="",$X8='Out_Dashboard'!$C$6),OR('Out_Dashboard'!$C$7="",$B8='Out_Dashboard'!$C$7)),1,0)) | Z8: =IF(AND($A8<>"",$S8<>"",$Y8=1),SUMPRODUCT(($A$8:$A8<>"")*($S$8:$S8<>"")*($Y$8:$Y8=1)),"") | AA8: =IF(AND($A8<>"",$T8<>"",$Y8=1),SUMPRODUCT(($A$8:$A8<>"")*($T$8:$T8<>"")*($Y$8:$Y8=1)),"") | AB8: ◄ EXAMPLE
J9: =IF($A9="","",IFERROR(INDEX('Ref_Crosswalk'!$F$2:$F$500,MATCH($A9,'Ref_Crosswalk'!$A$2:$A$500,0)),"UNKNOWN")) | K9: =IF($A9="","",IFERROR(INDEX('Ref_Tolerance'!$B$2:$B$9,MATCH($J9,'Ref_Tolerance'!$A$2:$A$9,0)),"")) | L9: =IF($A9="","",IFERROR(INDEX('Ref_Tolerance'!$D$2:$D$9,MATCH($J9,'Ref_Tolerance'!$A$2:$A$9,0)),"")) | M9: =IF($A9="","",IFERROR(ABS(N($D9))/N($C9),0)) | N9: =IF($A9="","",IFERROR(N($E9)/N($C9),0)) | O9: =IF($A9="",0,IFERROR(SUMPRODUCT(($A$8:$A$307=$A9)*($P$8:$P$307="FAIL")*($U$8:$U$307>$V9)*($U$8:$U$307<=$U9)),0)) | P9: =IF($A9="","",IFERROR(IF(NOT(ISNUMBER($K9)),"CHECK",IF($L9="MARGIN",IF($N9<=$K9,"PASS","FAIL"),IF($M9<=$K9,"PASS","FAIL"))),"CHECK")) | Q9: =IF($A9="","",IFERROR(INDEX('Ref_Tolerance'!$E$2:$E$9,MATCH($J9,'Ref_Tolerance'!$A$2:$A$9,0)),"")) | R9: =IF($A9="","",IFERROR(IF($O9=0,"CLEAR",IF($O9=1,"MFR DUE - MANAGER",IF($O9=2,"MFR DUE - FSS/CC SIGNATURE REQUIRED","INVESTIGATION + REPORT OF SURVEY; MSG/CC NOTIFIED"))),"")) | S9: =IF($A9="","",IF($O9=2,"WATCH - ONE MORE MISS TRIGGERS INVESTIGATION","")) | T9: =IF($A9="","",IFERROR(IF(AND($O9>=1,$F9<>"Y"),"MFR NOT SUBMITTED",IF(AND($O9>=2,$G9<>"Y"),"FSS/CC SIGNATURE MISSING",IF(AND($O9>=3,$H9<>"Y"),"INVESTIGATION NOT OPENED",""))),"")) | U9: =IF($A9="",0,IFERROR(MATCH($B9,'Ref_Calendar'!$A$2:$A$500,0),0)) | V9: =IF($A9="",0,IFERROR(SUMPRODUCT(MAX(($A$8:$A$307=$A9)*($P$8:$P$307="PASS")*($U$8:$U$307<=$U9)*$U$8:$U$307)),0)) | W9: =IF($A9="","",IFERROR(INDEX('Ref_Crosswalk'!$E$2:$E$500,MATCH($A9,'Ref_Crosswalk'!$A$2:$A$500,0)),"")) | X9: =IF($A9="","",IFERROR(INDEX('Ref_Crosswalk'!$C$2:$C$500,MATCH($A9,'Ref_Crosswalk'!$A$2:$A$500,0)),"")) | Y9: =IF($A9="",0,IF(AND(OR('Out_Dashboard'!$C$5="",$W9='Out_Dashboard'!$C$5),OR('Out_Dashboard'!$C$6="",$X9='Out_Dashboard'!$C$6),OR('Out_Dashboard'!$C$7="",$B9='Out_Dashboard'!$C$7)),1,0)) | Z9: =IF(AND($A9<>"",$S9<>"",$Y9=1),SUMPRODUCT(($A$8:$A9<>"")*($S$8:$S9<>"")*($Y$8:$Y9=1)),"") | AA9: =IF(AND($A9<>"",$T9<>"",$Y9=1),SUMPRODUCT(($A$8:$A9<>"")*($T$8:$T9<>"")*($Y$8:$Y9=1)),"")
J10: =IF($A10="","",IFERROR(INDEX('Ref_Crosswalk'!$F$2:$F$500,MATCH($A10,'Ref_Crosswalk'!$A$2:$A$500,0)),"UNKNOWN")) | K10: =IF($A10="","",IFERROR(INDEX('Ref_Tolerance'!$B$2:$B$9,MATCH($J10,'Ref_Tolerance'!$A$2:$A$9,0)),"")) | L10: =IF($A10="","",IFERROR(INDEX('Ref_Tolerance'!$D$2:$D$9,MATCH($J10,'Ref_Tolerance'!$A$2:$A$9,0)),"")) | M10: =IF($A10="","",IFERROR(ABS(N($D10))/N($C10),0)) | N10: =IF($A10="","",IFERROR(N($E10)/N($C10),0)) | O10: =IF($A10="",0,IFERROR(SUMPRODUCT(($A$8:$A$307=$A10)*($P$8:$P$307="FAIL")*($U$8:$U$307>$V10)*($U$8:$U$307<=$U10)),0)) | P10: =IF($A10="","",IFERROR(IF(NOT(ISNUMBER($K10)),"CHECK",IF($L10="MARGIN",IF($N10<=$K10,"PASS","FAIL"),IF($M10<=$K10,"PASS","FAIL"))),"CHECK")) | Q10: =IF($A10="","",IFERROR(INDEX('Ref_Tolerance'!$E$2:$E$9,MATCH($J10,'Ref_Tolerance'!$A$2:$A$9,0)),"")) | R10: =IF($A10="","",IFERROR(IF($O10=0,"CLEAR",IF($O10=1,"MFR DUE - MANAGER",IF($O10=2,"MFR DUE - FSS/CC SIGNATURE REQUIRED","INVESTIGATION + REPORT OF SURVEY; MSG/CC NOTIFIED"))),"")) | S10: =IF($A10="","",IF($O10=2,"WATCH - ONE MORE MISS TRIGGERS INVESTIGATION","")) | T10: =IF($A10="","",IFERROR(IF(AND($O10>=1,$F10<>"Y"),"MFR NOT SUBMITTED",IF(AND($O10>=2,$G10<>"Y"),"FSS/CC SIGNATURE MISSING",IF(AND($O10>=3,$H10<>"Y"),"INVESTIGATION NOT OPENED",""))),"")) | U10: =IF($A10="",0,IFERROR(MATCH($B10,'Ref_Calendar'!$A$2:$A$500,0),0)) | V10: =IF($A10="",0,IFERROR(SUMPRODUCT(MAX(($A$8:$A$307=$A10)*($P$8:$P$307="PASS")*($U$8:$U$307<=$U10)*$U$8:$U$307)),0)) | W10: =IF($A10="","",IFERROR(INDEX('Ref_Crosswalk'!$E$2:$E$500,MATCH($A10,'Ref_Crosswalk'!$A$2:$A$500,0)),"")) | X10: =IF($A10="","",IFERROR(INDEX('Ref_Crosswalk'!$C$2:$C$500,MATCH($A10,'Ref_Crosswalk'!$A$2:$A$500,0)),"")) | Y10: =IF($A10="",0,IF(AND(OR('Out_Dashboard'!$C$5="",$W10='Out_Dashboard'!$C$5),OR('Out_Dashboard'!$C$6="",$X10='Out_Dashboard'!$C$6),OR('Out_Dashboard'!$C$7="",$B10='Out_Dashboard'!$C$7)),1,0)) | Z10: =IF(AND($A10<>"",$S10<>"",$Y10=1),SUMPRODUCT(($A$8:$A10<>"")*($S$8:$S10<>"")*($Y$8:$Y10=1)),"") | AA10: =IF(AND($A10<>"",$T10<>"",$Y10=1),SUMPRODUCT(($A$8:$A10<>"")*($T$8:$T10<>"")*($Y$8:$Y10=1)),"")
J11: =IF($A11="","",IFERROR(INDEX('Ref_Crosswalk'!$F$2:$F$500,MATCH($A11,'Ref_Crosswalk'!$A$2:$A$500,0)),"UNKNOWN")) | K11: =IF($A11="","",IFERROR(INDEX('Ref_Tolerance'!$B$2:$B$9,MATCH($J11,'Ref_Tolerance'!$A$2:$A$9,0)),"")) | L11: =IF($A11="","",IFERROR(INDEX('Ref_Tolerance'!$D$2:$D$9,MATCH($J11,'Ref_Tolerance'!$A$2:$A$9,0)),"")) | M11: =IF($A11="","",IFERROR(ABS(N($D11))/N($C11),0)) | N11: =IF($A11="","",IFERROR(N($E11)/N($C11),0)) | O11: =IF($A11="",0,IFERROR(SUMPRODUCT(($A$8:$A$307=$A11)*($P$8:$P$307="FAIL")*($U$8:$U$307>$V11)*($U$8:$U$307<=$U11)),0)) | P11: =IF($A11="","",IFERROR(IF(NOT(ISNUMBER($K11)),"CHECK",IF($L11="MARGIN",IF($N11<=$K11,"PASS","FAIL"),IF($M11<=$K11,"PASS","FAIL"))),"CHECK")) | Q11: =IF($A11="","",IFERROR(INDEX('Ref_Tolerance'!$E$2:$E$9,MATCH($J11,'Ref_Tolerance'!$A$2:$A$9,0)),"")) | R11: =IF($A11="","",IFERROR(IF($O11=0,"CLEAR",IF($O11=1,"MFR DUE - MANAGER",IF($O11=2,"MFR DUE - FSS/CC SIGNATURE REQUIRED","INVESTIGATION + REPORT OF SURVEY; MSG/CC NOTIFIED"))),"")) | S11: =IF($A11="","",IF($O11=2,"WATCH - ONE MORE MISS TRIGGERS INVESTIGATION","")) | T11: =IF($A11="","",IFERROR(IF(AND($O11>=1,$F11<>"Y"),"MFR NOT SUBMITTED",IF(AND($O11>=2,$G11<>"Y"),"FSS/CC SIGNATURE MISSING",IF(AND($O11>=3,$H11<>"Y"),"INVESTIGATION NOT OPENED",""))),"")) | U11: =IF($A11="",0,IFERROR(MATCH($B11,'Ref_Calendar'!$A$2:$A$500,0),0)) | V11: =IF($A11="",0,IFERROR(SUMPRODUCT(MAX(($A$8:$A$307=$A11)*($P$8:$P$307="PASS")*($U$8:$U$307<=$U11)*$U$8:$U$307)),0)) | W11: =IF($A11="","",IFERROR(INDEX('Ref_Crosswalk'!$E$2:$E$500,MATCH($A11,'Ref_Crosswalk'!$A$2:$A$500,0)),"")) | X11: =IF($A11="","",IFERROR(INDEX('Ref_Crosswalk'!$C$2:$C$500,MATCH($A11,'Ref_Crosswalk'!$A$2:$A$500,0)),"")) | Y11: =IF($A11="",0,IF(AND(OR('Out_Dashboard'!$C$5="",$W11='Out_Dashboard'!$C$5),OR('Out_Dashboard'!$C$6="",$X11='Out_Dashboard'!$C$6),OR('Out_Dashboard'!$C$7="",$B11='Out_Dashboard'!$C$7)),1,0)) | Z11: =IF(AND($A11<>"",$S11<>"",$Y11=1),SUMPRODUCT(($A$8:$A11<>"")*($S$8:$S11<>"")*($Y$8:$Y11=1)),"") | AA11: =IF(AND($A11<>"",$T11<>"",$Y11=1),SUMPRODUCT(($A$8:$A11<>"")*($T$8:$T11<>"")*($Y$8:$Y11=1)),"")
J12: =IF($A12="","",IFERROR(INDEX('Ref_Crosswalk'!$F$2:$F$500,MATCH($A12,'Ref_Crosswalk'!$A$2:$A$500,0)),"UNKNOWN")) | K12: =IF($A12="","",IFERROR(INDEX('Ref_Tolerance'!$B$2:$B$9,MATCH($J12,'Ref_Tolerance'!$A$2:$A$9,0)),"")) | L12: =IF($A12="","",IFERROR(INDEX('Ref_Tolerance'!$D$2:$D$9,MATCH($J12,'Ref_Tolerance'!$A$2:$A$9,0)),"")) | M12: =IF($A12="","",IFERROR(ABS(N($D12))/N($C12),0)) | N12: =IF($A12="","",IFERROR(N($E12)/N($C12),0)) | O12: =IF($A12="",0,IFERROR(SUMPRODUCT(($A$8:$A$307=$A12)*($P$8:$P$307="FAIL")*($U$8:$U$307>$V12)*($U$8:$U$307<=$U12)),0)) | P12: =IF($A12="","",IFERROR(IF(NOT(ISNUMBER($K12)),"CHECK",IF($L12="MARGIN",IF($N12<=$K12,"PASS","FAIL"),IF($M12<=$K12,"PASS","FAIL"))),"CHECK")) | Q12: =IF($A12="","",IFERROR(INDEX('Ref_Tolerance'!$E$2:$E$9,MATCH($J12,'Ref_Tolerance'!$A$2:$A$9,0)),"")) | R12: =IF($A12="","",IFERROR(IF($O12=0,"CLEAR",IF($O12=1,"MFR DUE - MANAGER",IF($O12=2,"MFR DUE - FSS/CC SIGNATURE REQUIRED","INVESTIGATION + REPORT OF SURVEY; MSG/CC NOTIFIED"))),"")) | S12: =IF($A12="","",IF($O12=2,"WATCH - ONE MORE MISS TRIGGERS INVESTIGATION","")) | T12: =IF($A12="","",IFERROR(IF(AND($O12>=1,$F12<>"Y"),"MFR NOT SUBMITTED",IF(AND($O12>=2,$G12<>"Y"),"FSS/CC SIGNATURE MISSING",IF(AND($O12>=3,$H12<>"Y"),"INVESTIGATION NOT OPENED",""))),"")) | U12: =IF($A12="",0,IFERROR(MATCH($B12,'Ref_Calendar'!$A$2:$A$500,0),0)) | V12: =IF($A12="",0,IFERROR(SUMPRODUCT(MAX(($A$8:$A$307=$A12)*($P$8:$P$307="PASS")*($U$8:$U$307<=$U12)*$U$8:$U$307)),0)) | W12: =IF($A12="","",IFERROR(INDEX('Ref_Crosswalk'!$E$2:$E$500,MATCH($A12,'Ref_Crosswalk'!$A$2:$A$500,0)),"")) | X12: =IF($A12="","",IFERROR(INDEX('Ref_Crosswalk'!$C$2:$C$500,MATCH($A12,'Ref_Crosswalk'!$A$2:$A$500,0)),"")) | Y12: =IF($A12="",0,IF(AND(OR('Out_Dashboard'!$C$5="",$W12='Out_Dashboard'!$C$5),OR('Out_Dashboard'!$C$6="",$X12='Out_Dashboard'!$C$6),OR('Out_Dashboard'!$C$7="",$B12='Out_Dashboard'!$C$7)),1,0)) | Z12: =IF(AND($A12<>"",$S12<>"",$Y12=1),SUMPRODUCT(($A$8:$A12<>"")*($S$8:$S12<>"")*($Y$8:$Y12=1)),"") | AA12: =IF(AND($A12<>"",$T12<>"",$Y12=1),SUMPRODUCT(($A$8:$A12<>"")*($T$8:$T12<>"")*($Y$8:$Y12=1)),"")
J13: =IF($A13="","",IFERROR(INDEX('Ref_Crosswalk'!$F$2:$F$500,MATCH($A13,'Ref_Crosswalk'!$A$2:$A$500,0)),"UNKNOWN")) | K13: =IF($A13="","",IFERROR(INDEX('Ref_Tolerance'!$B$2:$B$9,MATCH($J13,'Ref_Tolerance'!$A$2:$A$9,0)),"")) | L13: =IF($A13="","",IFERROR(INDEX('Ref_Tolerance'!$D$2:$D$9,MATCH($J13,'Ref_Tolerance'!$A$2:$A$9,0)),"")) | M13: =IF($A13="","",IFERROR(ABS(N($D13))/N($C13),0)) | N13: =IF($A13="","",IFERROR(N($E13)/N($C13),0)) | O13: =IF($A13="",0,IFERROR(SUMPRODUCT(($A$8:$A$307=$A13)*($P$8:$P$307="FAIL")*($U$8:$U$307>$V13)*($U$8:$U$307<=$U13)),0)) | P13: =IF($A13="","",IFERROR(IF(NOT(ISNUMBER($K13)),"CHECK",IF($L13="MARGIN",IF($N13<=$K13,"PASS","FAIL"),IF($M13<=$K13,"PASS","FAIL"))),"CHECK")) | Q13: =IF($A13="","",IFERROR(INDEX('Ref_Tolerance'!$E$2:$E$9,MATCH($J13,'Ref_Tolerance'!$A$2:$A$9,0)),"")) | R13: =IF($A13="","",IFERROR(IF($O13=0,"CLEAR",IF($O13=1,"MFR DUE - MANAGER",IF($O13=2,"MFR DUE - FSS/CC SIGNATURE REQUIRED","INVESTIGATION + REPORT OF SURVEY; MSG/CC NOTIFIED"))),"")) | S13: =IF($A13="","",IF($O13=2,"WATCH - ONE MORE MISS TRIGGERS INVESTIGATION","")) | T13: =IF($A13="","",IFERROR(IF(AND($O13>=1,$F13<>"Y"),"MFR NOT SUBMITTED",IF(AND($O13>=2,$G13<>"Y"),"FSS/CC SIGNATURE MISSING",IF(AND($O13>=3,$H13<>"Y"),"INVESTIGATION NOT OPENED",""))),"")) | U13: =IF($A13="",0,IFERROR(MATCH($B13,'Ref_Calendar'!$A$2:$A$500,0),0)) | V13: =IF($A13="",0,IFERROR(SUMPRODUCT(MAX(($A$8:$A$307=$A13)*($P$8:$P$307="PASS")*($U$8:$U$307<=$U13)*$U$8:$U$307)),0)) | W13: =IF($A13="","",IFERROR(INDEX('Ref_Crosswalk'!$E$2:$E$500,MATCH($A13,'Ref_Crosswalk'!$A$2:$A$500,0)),"")) | X13: =IF($A13="","",IFERROR(INDEX('Ref_Crosswalk'!$C$2:$C$500,MATCH($A13,'Ref_Crosswalk'!$A$2:$A$500,0)),"")) | Y13: =IF($A13="",0,IF(AND(OR('Out_Dashboard'!$C$5="",$W13='Out_Dashboard'!$C$5),OR('Out_Dashboard'!$C$6="",$X13='Out_Dashboard'!$C$6),OR('Out_Dashboard'!$C$7="",$B13='Out_Dashboard'!$C$7)),1,0)) | Z13: =IF(AND($A13<>"",$S13<>"",$Y13=1),SUMPRODUCT(($A$8:$A13<>"")*($S$8:$S13<>"")*($Y$8:$Y13=1)),"") | AA13: =IF(AND($A13<>"",$T13<>"",$Y13=1),SUMPRODUCT(($A$8:$A13<>"")*($T$8:$T13<>"")*($Y$8:$Y13=1)),"")
J14: =IF($A14="","",IFERROR(INDEX('Ref_Crosswalk'!$F$2:$F$500,MATCH($A14,'Ref_Crosswalk'!$A$2:$A$500,0)),"UNKNOWN")) | K14: =IF($A14="","",IFERROR(INDEX('Ref_Tolerance'!$B$2:$B$9,MATCH($J14,'Ref_Tolerance'!$A$2:$A$9,0)),"")) | L14: =IF($A14="","",IFERROR(INDEX('Ref_Tolerance'!$D$2:$D$9,MATCH($J14,'Ref_Tolerance'!$A$2:$A$9,0)),"")) | M14: =IF($A14="","",IFERROR(ABS(N($D14))/N($C14),0)) | N14: =IF($A14="","",IFERROR(N($E14)/N($C14),0)) | O14: =IF($A14="",0,IFERROR(SUMPRODUCT(($A$8:$A$307=$A14)*($P$8:$P$307="FAIL")*($U$8:$U$307>$V14)*($U$8:$U$307<=$U14)),0)) | P14: =IF($A14="","",IFERROR(IF(NOT(ISNUMBER($K14)),"CHECK",IF($L14="MARGIN",IF($N14<=$K14,"PASS","FAIL"),IF($M14<=$K14,"PASS","FAIL"))),"CHECK")) | Q14: =IF($A14="","",IFERROR(INDEX('Ref_Tolerance'!$E$2:$E$9,MATCH($J14,'Ref_Tolerance'!$A$2:$A$9,0)),"")) | R14: =IF($A14="","",IFERROR(IF($O14=0,"CLEAR",IF($O14=1,"MFR DUE - MANAGER",IF($O14=2,"MFR DUE - FSS/CC SIGNATURE REQUIRED","INVESTIGATION + REPORT OF SURVEY; MSG/CC NOTIFIED"))),"")) | S14: =IF($A14="","",IF($O14=2,"WATCH - ONE MORE MISS TRIGGERS INVESTIGATION","")) | T14: =IF($A14="","",IFERROR(IF(AND($O14>=1,$F14<>"Y"),"MFR NOT SUBMITTED",IF(AND($O14>=2,$G14<>"Y"),"FSS/CC SIGNATURE MISSING",IF(AND($O14>=3,$H14<>"Y"),"INVESTIGATION NOT OPENED",""))),"")) | U14: =IF($A14="",0,IFERROR(MATCH($B14,'Ref_Calendar'!$A$2:$A$500,0),0)) | V14: =IF($A14="",0,IFERROR(SUMPRODUCT(MAX(($A$8:$A$307=$A14)*($P$8:$P$307="PASS")*($U$8:$U$307<=$U14)*$U$8:$U$307)),0)) | W14: =IF($A14="","",IFERROR(INDEX('Ref_Crosswalk'!$E$2:$E$500,MATCH($A14,'Ref_Crosswalk'!$A$2:$A$500,0)),"")) | X14: =IF($A14="","",IFERROR(INDEX('Ref_Crosswalk'!$C$2:$C$500,MATCH($A14,'Ref_Crosswalk'!$A$2:$A$500,0)),"")) | Y14: =IF($A14="",0,IF(AND(OR('Out_Dashboard'!$C$5="",$W14='Out_Dashboard'!$C$5),OR('Out_Dashboard'!$C$6="",$X14='Out_Dashboard'!$C$6),OR('Out_Dashboard'!$C$7="",$B14='Out_Dashboard'!$C$7)),1,0)) | Z14: =IF(AND($A14<>"",$S14<>"",$Y14=1),SUMPRODUCT(($A$8:$A14<>"")*($S$8:$S14<>"")*($Y$8:$Y14=1)),"") | AA14: =IF(AND($A14<>"",$T14<>"",$Y14=1),SUMPRODUCT(($A$8:$A14<>"")*($T$8:$T14<>"")*($Y$8:$Y14=1)),"")
J15: =IF($A15="","",IFERROR(INDEX('Ref_Crosswalk'!$F$2:$F$500,MATCH($A15,'Ref_Crosswalk'!$A$2:$A$500,0)),"UNKNOWN")) | K15: =IF($A15="","",IFERROR(INDEX('Ref_Tolerance'!$B$2:$B$9,MATCH($J15,'Ref_Tolerance'!$A$2:$A$9,0)),"")) | L15: =IF($A15="","",IFERROR(INDEX('Ref_Tolerance'!$D$2:$D$9,MATCH($J15,'Ref_Tolerance'!$A$2:$A$9,0)),"")) | M15: =IF($A15="","",IFERROR(ABS(N($D15))/N($C15),0)) | N15: =IF($A15="","",IFERROR(N($E15)/N($C15),0)) | O15: =IF($A15="",0,IFERROR(SUMPRODUCT(($A$8:$A$307=$A15)*($P$8:$P$307="FAIL")*($U$8:$U$307>$V15)*($U$8:$U$307<=$U15)),0)) | P15: =IF($A15="","",IFERROR(IF(NOT(ISNUMBER($K15)),"CHECK",IF($L15="MARGIN",IF($N15<=$K15,"PASS","FAIL"),IF($M15<=$K15,"PASS","FAIL"))),"CHECK")) | Q15: =IF($A15="","",IFERROR(INDEX('Ref_Tolerance'!$E$2:$E$9,MATCH($J15,'Ref_Tolerance'!$A$2:$A$9,0)),"")) | R15: =IF($A15="","",IFERROR(IF($O15=0,"CLEAR",IF($O15=1,"MFR DUE - MANAGER",IF($O15=2,"MFR DUE - FSS/CC SIGNATURE REQUIRED","INVESTIGATION + REPORT OF SURVEY; MSG/CC NOTIFIED"))),"")) | S15: =IF($A15="","",IF($O15=2,"WATCH - ONE MORE MISS TRIGGERS INVESTIGATION","")) | T15: =IF($A15="","",IFERROR(IF(AND($O15>=1,$F15<>"Y"),"MFR NOT SUBMITTED",IF(AND($O15>=2,$G15<>"Y"),"FSS/CC SIGNATURE MISSING",IF(AND($O15>=3,$H15<>"Y"),"INVESTIGATION NOT OPENED",""))),"")) | U15: =IF($A15="",0,IFERROR(MATCH($B15,'Ref_Calendar'!$A$2:$A$500,0),0)) | V15: =IF($A15="",0,IFERROR(SUMPRODUCT(MAX(($A$8:$A$307=$A15)*($P$8:$P$307="PASS")*($U$8:$U$307<=$U15)*$U$8:$U$307)),0)) | W15: =IF($A15="","",IFERROR(INDEX('Ref_Crosswalk'!$E$2:$E$500,MATCH($A15,'Ref_Crosswalk'!$A$2:$A$500,0)),"")) | X15: =IF($A15="","",IFERROR(INDEX('Ref_Crosswalk'!$C$2:$C$500,MATCH($A15,'Ref_Crosswalk'!$A$2:$A$500,0)),"")) | Y15: =IF($A15="",0,IF(AND(OR('Out_Dashboard'!$C$5="",$W15='Out_Dashboard'!$C$5),OR('Out_Dashboard'!$C$6="",$X15='Out_Dashboard'!$C$6),OR('Out_Dashboard'!$C$7="",$B15='Out_Dashboard'!$C$7)),1,0)) | Z15: =IF(AND($A15<>"",$S15<>"",$Y15=1),SUMPRODUCT(($A$8:$A15<>"")*($S$8:$S15<>"")*($Y$8:$Y15=1)),"") | AA15: =IF(AND($A15<>"",$T15<>"",$Y15=1),SUMPRODUCT(($A$8:$A15<>"")*($T$8:$T15<>"")*($Y$8:$Y15=1)),"")
J16: =IF($A16="","",IFERROR(INDEX('Ref_Crosswalk'!$F$2:$F$500,MATCH($A16,'Ref_Crosswalk'!$A$2:$A$500,0)),"UNKNOWN")) | K16: =IF($A16="","",IFERROR(INDEX('Ref_Tolerance'!$B$2:$B$9,MATCH($J16,'Ref_Tolerance'!$A$2:$A$9,0)),"")) | L16: =IF($A16="","",IFERROR(INDEX('Ref_Tolerance'!$D$2:$D$9,MATCH($J16,'Ref_Tolerance'!$A$2:$A$9,0)),"")) | M16: =IF($A16="","",IFERROR(ABS(N($D16))/N($C16),0)) | N16: =IF($A16="","",IFERROR(N($E16)/N($C16),0)) | O16: =IF($A16="",0,IFERROR(SUMPRODUCT(($A$8:$A$307=$A16)*($P$8:$P$307="FAIL")*($U$8:$U$307>$V16)*($U$8:$U$307<=$U16)),0)) | P16: =IF($A16="","",IFERROR(IF(NOT(ISNUMBER($K16)),"CHECK",IF($L16="MARGIN",IF($N16<=$K16,"PASS","FAIL"),IF($M16<=$K16,"PASS","FAIL"))),"CHECK")) | Q16: =IF($A16="","",IFERROR(INDEX('Ref_Tolerance'!$E$2:$E$9,MATCH($J16,'Ref_Tolerance'!$A$2:$A$9,0)),"")) | R16: =IF($A16="","",IFERROR(IF($O16=0,"CLEAR",IF($O16=1,"MFR DUE - MANAGER",IF($O16=2,"MFR DUE - FSS/CC SIGNATURE REQUIRED","INVESTIGATION + REPORT OF SURVEY; MSG/CC NOTIFIED"))),"")) | S16: =IF($A16="","",IF($O16=2,"WATCH - ONE MORE MISS TRIGGERS INVESTIGATION","")) | T16: =IF($A16="","",IFERROR(IF(AND($O16>=1,$F16<>"Y"),"MFR NOT SUBMITTED",IF(AND($O16>=2,$G16<>"Y"),"FSS/CC SIGNATURE MISSING",IF(AND($O16>=3,$H16<>"Y"),"INVESTIGATION NOT OPENED",""))),"")) | U16: =IF($A16="",0,IFERROR(MATCH($B16,'Ref_Calendar'!$A$2:$A$500,0),0)) | V16: =IF($A16="",0,IFERROR(SUMPRODUCT(MAX(($A$8:$A$307=$A16)*($P$8:$P$307="PASS")*($U$8:$U$307<=$U16)*$U$8:$U$307)),0)) | W16: =IF($A16="","",IFERROR(INDEX('Ref_Crosswalk'!$E$2:$E$500,MATCH($A16,'Ref_Crosswalk'!$A$2:$A$500,0)),"")) | X16: =IF($A16="","",IFERROR(INDEX('Ref_Crosswalk'!$C$2:$C$500,MATCH($A16,'Ref_Crosswalk'!$A$2:$A$500,0)),"")) | Y16: =IF($A16="",0,IF(AND(OR('Out_Dashboard'!$C$5="",$W16='Out_Dashboard'!$C$5),OR('Out_Dashboard'!$C$6="",$X16='Out_Dashboard'!$C$6),OR('Out_Dashboard'!$C$7="",$B16='Out_Dashboard'!$C$7)),1,0)) | Z16: =IF(AND($A16<>"",$S16<>"",$Y16=1),SUMPRODUCT(($A$8:$A16<>"")*($S$8:$S16<>"")*($Y$8:$Y16=1)),"") | AA16: =IF(AND($A16<>"",$T16<>"",$Y16=1),SUMPRODUCT(($A$8:$A16<>"")*($T$8:$T16<>"")*($Y$8:$Y16=1)),"")
J17: =IF($A17="","",IFERROR(INDEX('Ref_Crosswalk'!$F$2:$F$500,MATCH($A17,'Ref_Crosswalk'!$A$2:$A$500,0)),"UNKNOWN")) | K17: =IF($A17="","",IFERROR(INDEX('Ref_Tolerance'!$B$2:$B$9,MATCH($J17,'Ref_Tolerance'!$A$2:$A$9,0)),"")) | L17: =IF($A17="","",IFERROR(INDEX('Ref_Tolerance'!$D$2:$D$9,MATCH($J17,'Ref_Tolerance'!$A$2:$A$9,0)),"")) | M17: =IF($A17="","",IFERROR(ABS(N($D17))/N($C17),0)) | N17: =IF($A17="","",IFERROR(N($E17)/N($C17),0)) | O17: =IF($A17="",0,IFERROR(SUMPRODUCT(($A$8:$A$307=$A17)*($P$8:$P$307="FAIL")*($U$8:$U$307>$V17)*($U$8:$U$307<=$U17)),0)) | P17: =IF($A17="","",IFERROR(IF(NOT(ISNUMBER($K17)),"CHECK",IF($L17="MARGIN",IF($N17<=$K17,"PASS","FAIL"),IF($M17<=$K17,"PASS","FAIL"))),"CHECK")) | Q17: =IF($A17="","",IFERROR(INDEX('Ref_Tolerance'!$E$2:$E$9,MATCH($J17,'Ref_Tolerance'!$A$2:$A$9,0)),"")) | R17: =IF($A17="","",IFERROR(IF($O17=0,"CLEAR",IF($O17=1,"MFR DUE - MANAGER",IF($O17=2,"MFR DUE - FSS/CC SIGNATURE REQUIRED","INVESTIGATION + REPORT OF SURVEY; MSG/CC NOTIFIED"))),"")) | S17: =IF($A17="","",IF($O17=2,"WATCH - ONE MORE MISS TRIGGERS INVESTIGATION","")) | T17: =IF($A17="","",IFERROR(IF(AND($O17>=1,$F17<>"Y"),"MFR NOT SUBMITTED",IF(AND($O17>=2,$G17<>"Y"),"FSS/CC SIGNATURE MISSING",IF(AND($O17>=3,$H17<>"Y"),"INVESTIGATION NOT OPENED",""))),"")) | U17: =IF($A17="",0,IFERROR(MATCH($B17,'Ref_Calendar'!$A$2:$A$500,0),0)) | V17: =IF($A17="",0,IFERROR(SUMPRODUCT(MAX(($A$8:$A$307=$A17)*($P$8:$P$307="PASS")*($U$8:$U$307<=$U17)*$U$8:$U$307)),0)) | W17: =IF($A17="","",IFERROR(INDEX('Ref_Crosswalk'!$E$2:$E$500,MATCH($A17,'Ref_Crosswalk'!$A$2:$A$500,0)),"")) | X17: =IF($A17="","",IFERROR(INDEX('Ref_Crosswalk'!$C$2:$C$500,MATCH($A17,'Ref_Crosswalk'!$A$2:$A$500,0)),"")) | Y17: =IF($A17="",0,IF(AND(OR('Out_Dashboard'!$C$5="",$W17='Out_Dashboard'!$C$5),OR('Out_Dashboard'!$C$6="",$X17='Out_Dashboard'!$C$6),OR('Out_Dashboard'!$C$7="",$B17='Out_Dashboard'!$C$7)),1,0)) | Z17: =IF(AND($A17<>"",$S17<>"",$Y17=1),SUMPRODUCT(($A$8:$A17<>"")*($S$8:$S17<>"")*($Y$8:$Y17=1)),"") | AA17: =IF(AND($A17<>"",$T17<>"",$Y17=1),SUMPRODUCT(($A$8:$A17<>"")*($T$8:$T17<>"")*($Y$8:$Y17=1)),"")
J18: =IF($A18="","",IFERROR(INDEX('Ref_Crosswalk'!$F$2:$F$500,MATCH($A18,'Ref_Crosswalk'!$A$2:$A$500,0)),"UNKNOWN")) | K18: =IF($A18="","",IFERROR(INDEX('Ref_Tolerance'!$B$2:$B$9,MATCH($J18,'Ref_Tolerance'!$A$2:$A$9,0)),"")) | L18: =IF($A18="","",IFERROR(INDEX('Ref_Tolerance'!$D$2:$D$9,MATCH($J18,'Ref_Tolerance'!$A$2:$A$9,0)),"")) | M18: =IF($A18="","",IFERROR(ABS(N($D18))/N($C18),0)) | N18: =IF($A18="","",IFERROR(N($E18)/N($C18),0)) | O18: =IF($A18="",0,IFERROR(SUMPRODUCT(($A$8:$A$307=$A18)*($P$8:$P$307="FAIL")*($U$8:$U$307>$V18)*($U$8:$U$307<=$U18)),0)) | P18: =IF($A18="","",IFERROR(IF(NOT(ISNUMBER($K18)),"CHECK",IF($L18="MARGIN",IF($N18<=$K18,"PASS","FAIL"),IF($M18<=$K18,"PASS","FAIL"))),"CHECK")) | Q18: =IF($A18="","",IFERROR(INDEX('Ref_Tolerance'!$E$2:$E$9,MATCH($J18,'Ref_Tolerance'!$A$2:$A$9,0)),"")) | R18: =IF($A18="","",IFERROR(IF($O18=0,"CLEAR",IF($O18=1,"MFR DUE - MANAGER",IF($O18=2,"MFR DUE - FSS/CC SIGNATURE REQUIRED","INVESTIGATION + REPORT OF SURVEY; MSG/CC NOTIFIED"))),"")) | S18: =IF($A18="","",IF($O18=2,"WATCH - ONE MORE MISS TRIGGERS INVESTIGATION","")) | T18: =IF($A18="","",IFERROR(IF(AND($O18>=1,$F18<>"Y"),"MFR NOT SUBMITTED",IF(AND($O18>=2,$G18<>"Y"),"FSS/CC SIGNATURE MISSING",IF(AND($O18>=3,$H18<>"Y"),"INVESTIGATION NOT OPENED",""))),"")) | U18: =IF($A18="",0,IFERROR(MATCH($B18,'Ref_Calendar'!$A$2:$A$500,0),0)) | V18: =IF($A18="",0,IFERROR(SUMPRODUCT(MAX(($A$8:$A$307=$A18)*($P$8:$P$307="PASS")*($U$8:$U$307<=$U18)*$U$8:$U$307)),0)) | W18: =IF($A18="","",IFERROR(INDEX('Ref_Crosswalk'!$E$2:$E$500,MATCH($A18,'Ref_Crosswalk'!$A$2:$A$500,0)),"")) | X18: =IF($A18="","",IFERROR(INDEX('Ref_Crosswalk'!$C$2:$C$500,MATCH($A18,'Ref_Crosswalk'!$A$2:$A$500,0)),"")) | Y18: =IF($A18="",0,IF(AND(OR('Out_Dashboard'!$C$5="",$W18='Out_Dashboard'!$C$5),OR('Out_Dashboard'!$C$6="",$X18='Out_Dashboard'!$C$6),OR('Out_Dashboard'!$C$7="",$B18='Out_Dashboard'!$C$7)),1,0)) | Z18: =IF(AND($A18<>"",$S18<>"",$Y18=1),SUMPRODUCT(($A$8:$A18<>"")*($S$8:$S18<>"")*($Y$8:$Y18=1)),"") | AA18: =IF(AND($A18<>"",$T18<>"",$Y18=1),SUMPRODUCT(($A$8:$A18<>"")*($T$8:$T18<>"")*($Y$8:$Y18=1)),"")
J19: =IF($A19="","",IFERROR(INDEX('Ref_Crosswalk'!$F$2:$F$500,MATCH($A19,'Ref_Crosswalk'!$A$2:$A$500,0)),"UNKNOWN")) | K19: =IF($A19="","",IFERROR(INDEX('Ref_Tolerance'!$B$2:$B$9,MATCH($J19,'Ref_Tolerance'!$A$2:$A$9,0)),"")) | L19: =IF($A19="","",IFERROR(INDEX('Ref_Tolerance'!$D$2:$D$9,MATCH($J19,'Ref_Tolerance'!$A$2:$A$9,0)),"")) | M19: =IF($A19="","",IFERROR(ABS(N($D19))/N($C19),0)) | N19: =IF($A19="","",IFERROR(N($E19)/N($C19),0)) | O19: =IF($A19="",0,IFERROR(SUMPRODUCT(($A$8:$A$307=$A19)*($P$8:$P$307="FAIL")*($U$8:$U$307>$V19)*($U$8:$U$307<=$U19)),0)) | P19: =IF($A19="","",IFERROR(IF(NOT(ISNUMBER($K19)),"CHECK",IF($L19="MARGIN",IF($N19<=$K19,"PASS","FAIL"),IF($M19<=$K19,"PASS","FAIL"))),"CHECK")) | Q19: =IF($A19="","",IFERROR(INDEX('Ref_Tolerance'!$E$2:$E$9,MATCH($J19,'Ref_Tolerance'!$A$2:$A$9,0)),"")) | R19: =IF($A19="","",IFERROR(IF($O19=0,"CLEAR",IF($O19=1,"MFR DUE - MANAGER",IF($O19=2,"MFR DUE - FSS/CC SIGNATURE REQUIRED","INVESTIGATION + REPORT OF SURVEY; MSG/CC NOTIFIED"))),"")) | S19: =IF($A19="","",IF($O19=2,"WATCH - ONE MORE MISS TRIGGERS INVESTIGATION","")) | T19: =IF($A19="","",IFERROR(IF(AND($O19>=1,$F19<>"Y"),"MFR NOT SUBMITTED",IF(AND($O19>=2,$G19<>"Y"),"FSS/CC SIGNATURE MISSING",IF(AND($O19>=3,$H19<>"Y"),"INVESTIGATION NOT OPENED",""))),"")) | U19: =IF($A19="",0,IFERROR(MATCH($B19,'Ref_Calendar'!$A$2:$A$500,0),0)) | V19: =IF($A19="",0,IFERROR(SUMPRODUCT(MAX(($A$8:$A$307=$A19)*($P$8:$P$307="PASS")*($U$8:$U$307<=$U19)*$U$8:$U$307)),0)) | W19: =IF($A19="","",IFERROR(INDEX('Ref_Crosswalk'!$E$2:$E$500,MATCH($A19,'Ref_Crosswalk'!$A$2:$A$500,0)),"")) | X19: =IF($A19="","",IFERROR(INDEX('Ref_Crosswalk'!$C$2:$C$500,MATCH($A19,'Ref_Crosswalk'!$A$2:$A$500,0)),"")) | Y19: =IF($A19="",0,IF(AND(OR('Out_Dashboard'!$C$5="",$W19='Out_Dashboard'!$C$5),OR('Out_Dashboard'!$C$6="",$X19='Out_Dashboard'!$C$6),OR('Out_Dashboard'!$C$7="",$B19='Out_Dashboard'!$C$7)),1,0)) | Z19: =IF(AND($A19<>"",$S19<>"",$Y19=1),SUMPRODUCT(($A$8:$A19<>"")*($S$8:$S19<>"")*($Y$8:$Y19=1)),"") | AA19: =IF(AND($A19<>"",$T19<>"",$Y19=1),SUMPRODUCT(($A$8:$A19<>"")*($T$8:$T19<>"")*($Y$8:$Y19=1)),"")
J20: =IF($A20="","",IFERROR(INDEX('Ref_Crosswalk'!$F$2:$F$500,MATCH($A20,'Ref_Crosswalk'!$A$2:$A$500,0)),"UNKNOWN")) | K20: =IF($A20="","",IFERROR(INDEX('Ref_Tolerance'!$B$2:$B$9,MATCH($J20,'Ref_Tolerance'!$A$2:$A$9,0)),"")) | L20: =IF($A20="","",IFERROR(INDEX('Ref_Tolerance'!$D$2:$D$9,MATCH($J20,'Ref_Tolerance'!$A$2:$A$9,0)),"")) | M20: =IF($A20="","",IFERROR(ABS(N($D20))/N($C20),0)) | N20: =IF($A20="","",IFERROR(N($E20)/N($C20),0)) | O20: =IF($A20="",0,IFERROR(SUMPRODUCT(($A$8:$A$307=$A20)*($P$8:$P$307="FAIL")*($U$8:$U$307>$V20)*($U$8:$U$307<=$U20)),0)) | P20: =IF($A20="","",IFERROR(IF(NOT(ISNUMBER($K20)),"CHECK",IF($L20="MARGIN",IF($N20<=$K20,"PASS","FAIL"),IF($M20<=$K20,"PASS","FAIL"))),"CHECK")) | Q20: =IF($A20="","",IFERROR(INDEX('Ref_Tolerance'!$E$2:$E$9,MATCH($J20,'Ref_Tolerance'!$A$2:$A$9,0)),"")) | R20: =IF($A20="","",IFERROR(IF($O20=0,"CLEAR",IF($O20=1,"MFR DUE - MANAGER",IF($O20=2,"MFR DUE - FSS/CC SIGNATURE REQUIRED","INVESTIGATION + REPORT OF SURVEY; MSG/CC NOTIFIED"))),"")) | S20: =IF($A20="","",IF($O20=2,"WATCH - ONE MORE MISS TRIGGERS INVESTIGATION","")) | T20: =IF($A20="","",IFERROR(IF(AND($O20>=1,$F20<>"Y"),"MFR NOT SUBMITTED",IF(AND($O20>=2,$G20<>"Y"),"FSS/CC SIGNATURE MISSING",IF(AND($O20>=3,$H20<>"Y"),"INVESTIGATION NOT OPENED",""))),"")) | U20: =IF($A20="",0,IFERROR(MATCH($B20,'Ref_Calendar'!$A$2:$A$500,0),0)) | V20: =IF($A20="",0,IFERROR(SUMPRODUCT(MAX(($A$8:$A$307=$A20)*($P$8:$P$307="PASS")*($U$8:$U$307<=$U20)*$U$8:$U$307)),0)) | W20: =IF($A20="","",IFERROR(INDEX('Ref_Crosswalk'!$E$2:$E$500,MATCH($A20,'Ref_Crosswalk'!$A$2:$A$500,0)),"")) | X20: =IF($A20="","",IFERROR(INDEX('Ref_Crosswalk'!$C$2:$C$500,MATCH($A20,'Ref_Crosswalk'!$A$2:$A$500,0)),"")) | Y20: =IF($A20="",0,IF(AND(OR('Out_Dashboard'!$C$5="",$W20='Out_Dashboard'!$C$5),OR('Out_Dashboard'!$C$6="",$X20='Out_Dashboard'!$C$6),OR('Out_Dashboard'!$C$7="",$B20='Out_Dashboard'!$C$7)),1,0)) | Z20: =IF(AND($A20<>"",$S20<>"",$Y20=1),SUMPRODUCT(($A$8:$A20<>"")*($S$8:$S20<>"")*($Y$8:$Y20=1)),"") | AA20: =IF(AND($A20<>"",$T20<>"",$Y20=1),SUMPRODUCT(($A$8:$A20<>"")*($T$8:$T20<>"")*($Y$8:$Y20=1)),"")
... J307: =IF($A307="","",IFERROR(INDEX('Ref_Crosswalk'!$F$2:$F$500,MATCH($A307,'Ref_Crosswalk'!$A$2:$A$500,0)),"UNKNOWN")) | K307: =IF($A307="","",IFERROR(INDEX('Ref_Tolerance'!$B$2:$B$9,MATCH($J307,'Ref_Tolerance'!$A$2:$A$9,0)),"")) | L307: =IF($A307="","",IFERROR(INDEX('Ref_Tolerance'!$D$2:$D$9,MATCH($J307,'Ref_Tolerance'!$A$2:$A$9,0)),"")) | M307: =IF($A307="","",IFERROR(ABS(N($D307))/N($C307),0)) | N307: =IF($A307="","",IFERROR(N($E307)/N($C307),0)) | O307: =IF($A307="",0,IFERROR(SUMPRODUCT(($A$8:$A$307=$A307)*($P$8:$P$307="FAIL")*($U$8:$U$307>$V307)*($U$8:$U$307<=$U307)),0)) | P307: =IF($A307="","",IFERROR(IF(NOT(ISNUMBER($K307)),"CHECK",IF($L307="MARGIN",IF($N307<=$K307,"PASS","FAIL"),IF($M307<=$K307,"PASS","FAIL"))),"CHECK")) | Q307: =IF($A307="","",IFERROR(INDEX('Ref_Tolerance'!$E$2:$E$9,MATCH($J307,'Ref_Tolerance'!$A$2:$A$9,0)),"")) | R307: =IF($A307="","",IFERROR(IF($O307=0,"CLEAR",IF($O307=1,"MFR DUE - MANAGER",IF($O307=2,"MFR DUE - FSS/CC SIGNATURE REQUIRED","INVESTIGATION + REPORT OF SURVEY; MSG/CC NOTIFIED"))),"")) | S307: =IF($A307="","",IF($O307=2,"WATCH - ONE MORE MISS TRIGGERS INVESTIGATION","")) | T307: =IF($A307="","",IFERROR(IF(AND($O307>=1,$F307<>"Y"),"MFR NOT SUBMITTED",IF(AND($O307>=2,$G307<>"Y"),"FSS/CC SIGNATURE MISSING",IF(AND($O307>=3,$H307<>"Y"),"INVESTIGATION NOT OPENED",""))),"")) | U307: =IF($A307="",0,IFERROR(MATCH($B307,'Ref_Calendar'!$A$2:$A$500,0),0)) | V307: =IF($A307="",0,IFERROR(SUMPRODUCT(MAX(($A$8:$A$307=$A307)*($P$8:$P$307="PASS")*($U$8:$U$307<=$U307)*$U$8:$U$307)),0)) | W307: =IF($A307="","",IFERROR(INDEX('Ref_Crosswalk'!$E$2:$E$500,MATCH($A307,'Ref_Crosswalk'!$A$2:$A$500,0)),"")) | X307: =IF($A307="","",IFERROR(INDEX('Ref_Crosswalk'!$C$2:$C$500,MATCH($A307,'Ref_Crosswalk'!$A$2:$A$500,0)),"")) | Y307: =IF($A307="",0,IF(AND(OR('Out_Dashboard'!$C$5="",$W307='Out_Dashboard'!$C$5),OR('Out_Dashboard'!$C$6="",$X307='Out_Dashboard'!$C$6),OR('Out_Dashboard'!$C$7="",$B307='Out_Dashboard'!$C$7)),1,0)) | Z307: =IF(AND($A307<>"",$S307<>"",$Y307=1),SUMPRODUCT(($A$8:$A307<>"")*($S$8:$S307<>"")*($Y$8:$Y307=1)),"") | AA307: =IF(AND($A307<>"",$T307<>"",$Y307=1),SUMPRODUCT(($A$8:$A307<>"")*($T$8:$T307<>"")*($Y$8:$Y307=1)),"")

Sheet Out_Dashboard
A1: MISSION FEEDING — STATUS DASHBOARD
A2: Status as of: | C2: =TODAY()
A4: FILTERS (leave blank = all)
A5: MAJCOM:
A6: BASE_ID:
A7: PERIOD_KEY: | C7: FY2026-P07A
A9: HEADLINE — WHAT'S BROKEN
A10: DFACs out of tolerance: | D10: =SUMPRODUCT(('Out_ComplianceTracker'!$P$8:$P$307="FAIL")*('Out_ComplianceTracker'!$Y$8:$Y$307=1))
A11: Exceptions open: | D11: ="no data (Stage 3)"
A12: Dollars at risk: | D12: ="no data (Stage 3)"
A14: ESCALATION STATUS
A15: Month 1 — MFR due (manager): | D15: =SUMPRODUCT(('Out_ComplianceTracker'!$O$8:$O$307=1)*('Out_ComplianceTracker'!$Y$8:$Y$307=1))
A16: Month 2 — FSS/CC signature required: | D16: =SUMPRODUCT(('Out_ComplianceTracker'!$O$8:$O$307=2)*('Out_ComplianceTracker'!$Y$8:$Y$307=1))
A17: Month 3+ — investigation triggered: | D17: =SUMPRODUCT(('Out_ComplianceTracker'!$O$8:$O$307>=3)*('Out_ComplianceTracker'!$Y$8:$Y$307=1))
A19: WATCH LIST — one more miss triggers investigation | G19: watch count ► | H19: =SUMPRODUCT(('Out_ComplianceTracker'!$S$8:$S$307<>"")*('Out_ComplianceTracker'!$Y$8:$Y$307=1))
A20: DFAC_ID | B20: DFAC_NAME | C20: BASE_ID | D20: MAJCOM | E20: ESCALATION
A21: =IF($H$19=0,"Nothing on the watch list — you're clear.",IFERROR(INDEX('Out_ComplianceTracker'!$A$8:$A$307,MATCH(1,'Out_ComplianceTracker'!$Z$8:$Z$307,0)),"")) | B21: =IFERROR(INDEX('Ref_Crosswalk'!$B$2:$B$500,MATCH(INDEX('Out_ComplianceTracker'!$A$8:$A$307,MATCH(1,'Out_ComplianceTracker'!$Z$8:$Z$307,0)),'Ref_Crosswalk'!$A$2:$A$500,0)),"") | C21: =IFERROR(INDEX('Out_ComplianceTracker'!$X$8:$X$307,MATCH(1,'Out_ComplianceTracker'!$Z$8:$Z$307,0)),"") | D21: =IFERROR(INDEX('Out_ComplianceTracker'!$W$8:$W$307,MATCH(1,'Out_ComplianceTracker'!$Z$8:$Z$307,0)),"") | E21: =IFERROR(INDEX('Out_ComplianceTracker'!$R$8:$R$307,MATCH(1,'Out_ComplianceTracker'!$Z$8:$Z$307,0)),"")
A22: =IFERROR(INDEX('Out_ComplianceTracker'!$A$8:$A$307,MATCH(2,'Out_ComplianceTracker'!$Z$8:$Z$307,0)),"") | B22: =IFERROR(INDEX('Ref_Crosswalk'!$B$2:$B$500,MATCH(INDEX('Out_ComplianceTracker'!$A$8:$A$307,MATCH(2,'Out_ComplianceTracker'!$Z$8:$Z$307,0)),'Ref_Crosswalk'!$A$2:$A$500,0)),"") | C22: =IFERROR(INDEX('Out_ComplianceTracker'!$X$8:$X$307,MATCH(2,'Out_ComplianceTracker'!$Z$8:$Z$307,0)),"") | D22: =IFERROR(INDEX('Out_ComplianceTracker'!$W$8:$W$307,MATCH(2,'Out_ComplianceTracker'!$Z$8:$Z$307,0)),"") | E22: =IFERROR(INDEX('Out_ComplianceTracker'!$R$8:$R$307,MATCH(2,'Out_ComplianceTracker'!$Z$8:$Z$307,0)),"")
A23: =IFERROR(INDEX('Out_ComplianceTracker'!$A$8:$A$307,MATCH(3,'Out_ComplianceTracker'!$Z$8:$Z$307,0)),"") | B23: =IFERROR(INDEX('Ref_Crosswalk'!$B$2:$B$500,MATCH(INDEX('Out_ComplianceTracker'!$A$8:$A$307,MATCH(3,'Out_ComplianceTracker'!$Z$8:$Z$307,0)),'Ref_Crosswalk'!$A$2:$A$500,0)),"") | C23: =IFERROR(INDEX('Out_ComplianceTracker'!$X$8:$X$307,MATCH(3,'Out_ComplianceTracker'!$Z$8:$Z$307,0)),"") | D23: =IFERROR(INDEX('Out_ComplianceTracker'!$W$8:$W$307,MATCH(3,'Out_ComplianceTracker'!$Z$8:$Z$307,0)),"") | E23: =IFERROR(INDEX('Out_ComplianceTracker'!$R$8:$R$307,MATCH(3,'Out_ComplianceTracker'!$Z$8:$Z$307,0)),"")
A24: =IFERROR(INDEX('Out_ComplianceTracker'!$A$8:$A$307,MATCH(4,'Out_ComplianceTracker'!$Z$8:$Z$307,0)),"") | B24: =IFERROR(INDEX('Ref_Crosswalk'!$B$2:$B$500,MATCH(INDEX('Out_ComplianceTracker'!$A$8:$A$307,MATCH(4,'Out_ComplianceTracker'!$Z$8:$Z$307,0)),'Ref_Crosswalk'!$A$2:$A$500,0)),"") | C24: =IFERROR(INDEX('Out_ComplianceTracker'!$X$8:$X$307,MATCH(4,'Out_ComplianceTracker'!$Z$8:$Z$307,0)),"") | D24: =IFERROR(INDEX('Out_ComplianceTracker'!$W$8:$W$307,MATCH(4,'Out_ComplianceTracker'!$Z$8:$Z$307,0)),"") | E24: =IFERROR(INDEX('Out_ComplianceTracker'!$R$8:$R$307,MATCH(4,'Out_ComplianceTracker'!$Z$8:$Z$307,0)),"")
A25: =IFERROR(INDEX('Out_ComplianceTracker'!$A$8:$A$307,MATCH(5,'Out_ComplianceTracker'!$Z$8:$Z$307,0)),"") | B25: =IFERROR(INDEX('Ref_Crosswalk'!$B$2:$B$500,MATCH(INDEX('Out_ComplianceTracker'!$A$8:$A$307,MATCH(5,'Out_ComplianceTracker'!$Z$8:$Z$307,0)),'Ref_Crosswalk'!$A$2:$A$500,0)),"") | C25: =IFERROR(INDEX('Out_ComplianceTracker'!$X$8:$X$307,MATCH(5,'Out_ComplianceTracker'!$Z$8:$Z$307,0)),"") | D25: =IFERROR(INDEX('Out_ComplianceTracker'!$W$8:$W$307,MATCH(5,'Out_ComplianceTracker'!$Z$8:$Z$307,0)),"") | E25: =IFERROR(INDEX('Out_ComplianceTracker'!$R$8:$R$307,MATCH(5,'Out_ComplianceTracker'!$Z$8:$Z$307,0)),"")
A26: =IFERROR(INDEX('Out_ComplianceTracker'!$A$8:$A$307,MATCH(6,'Out_ComplianceTracker'!$Z$8:$Z$307,0)),"") | B26: =IFERROR(INDEX('Ref_Crosswalk'!$B$2:$B$500,MATCH(INDEX('Out_ComplianceTracker'!$A$8:$A$307,MATCH(6,'Out_ComplianceTracker'!$Z$8:$Z$307,0)),'Ref_Crosswalk'!$A$2:$A$500,0)),"") | C26: =IFERROR(INDEX('Out_ComplianceTracker'!$X$8:$X$307,MATCH(6,'Out_ComplianceTracker'!$Z$8:$Z$307,0)),"") | D26: =IFERROR(INDEX('Out_ComplianceTracker'!$W$8:$W$307,MATCH(6,'Out_ComplianceTracker'!$Z$8:$Z$307,0)),"") | E26: =IFERROR(INDEX('Out_ComplianceTracker'!$R$8:$R$307,MATCH(6,'Out_ComplianceTracker'!$Z$8:$Z$307,0)),"")
A27: =IFERROR(INDEX('Out_ComplianceTracker'!$A$8:$A$307,MATCH(7,'Out_ComplianceTracker'!$Z$8:$Z$307,0)),"") | B27: =IFERROR(INDEX('Ref_Crosswalk'!$B$2:$B$500,MATCH(INDEX('Out_ComplianceTracker'!$A$8:$A$307,MATCH(7,'Out_ComplianceTracker'!$Z$8:$Z$307,0)),'Ref_Crosswalk'!$A$2:$A$500,0)),"") | C27: =IFERROR(INDEX('Out_ComplianceTracker'!$X$8:$X$307,MATCH(7,'Out_ComplianceTracker'!$Z$8:$Z$307,0)),"") | D27: =IFERROR(INDEX('Out_ComplianceTracker'!$W$8:$W$307,MATCH(7,'Out_ComplianceTracker'!$Z$8:$Z$307,0)),"") | E27: =IFERROR(INDEX('Out_ComplianceTracker'!$R$8:$R$307,MATCH(7,'Out_ComplianceTracker'!$Z$8:$Z$307,0)),"")
A28: =IFERROR(INDEX('Out_ComplianceTracker'!$A$8:$A$307,MATCH(8,'Out_ComplianceTracker'!$Z$8:$Z$307,0)),"") | B28: =IFERROR(INDEX('Ref_Crosswalk'!$B$2:$B$500,MATCH(INDEX('Out_ComplianceTracker'!$A$8:$A$307,MATCH(8,'Out_ComplianceTracker'!$Z$8:$Z$307,0)),'Ref_Crosswalk'!$A$2:$A$500,0)),"") | C28: =IFERROR(INDEX('Out_ComplianceTracker'!$X$8:$X$307,MATCH(8,'Out_ComplianceTracker'!$Z$8:$Z$307,0)),"") | D28: =IFERROR(INDEX('Out_ComplianceTracker'!$W$8:$W$307,MATCH(8,'Out_ComplianceTracker'!$Z$8:$Z$307,0)),"") | E28: =IFERROR(INDEX('Out_ComplianceTracker'!$R$8:$R$307,MATCH(8,'Out_ComplianceTracker'!$Z$8:$Z$307,0)),"")
A29: =IFERROR(INDEX('Out_ComplianceTracker'!$A$8:$A$307,MATCH(9,'Out_ComplianceTracker'!$Z$8:$Z$307,0)),"") | B29: =IFERROR(INDEX('Ref_Crosswalk'!$B$2:$B$500,MATCH(INDEX('Out_ComplianceTracker'!$A$8:$A$307,MATCH(9,'Out_ComplianceTracker'!$Z$8:$Z$307,0)),'Ref_Crosswalk'!$A$2:$A$500,0)),"") | C29: =IFERROR(INDEX('Out_ComplianceTracker'!$X$8:$X$307,MATCH(9,'Out_ComplianceTracker'!$Z$8:$Z$307,0)),"") | D29: =IFERROR(INDEX('Out_ComplianceTracker'!$W$8:$W$307,MATCH(9,'Out_ComplianceTracker'!$Z$8:$Z$307,0)),"") | E29: =IFERROR(INDEX('Out_ComplianceTracker'!$R$8:$R$307,MATCH(9,'Out_ComplianceTracker'!$Z$8:$Z$307,0)),"")
A30: =IFERROR(INDEX('Out_ComplianceTracker'!$A$8:$A$307,MATCH(10,'Out_ComplianceTracker'!$Z$8:$Z$307,0)),"") | B30: =IFERROR(INDEX('Ref_Crosswalk'!$B$2:$B$500,MATCH(INDEX('Out_ComplianceTracker'!$A$8:$A$307,MATCH(10,'Out_ComplianceTracker'!$Z$8:$Z$307,0)),'Ref_Crosswalk'!$A$2:$A$500,0)),"") | C30: =IFERROR(INDEX('Out_ComplianceTracker'!$X$8:$X$307,MATCH(10,'Out_ComplianceTracker'!$Z$8:$Z$307,0)),"") | D30: =IFERROR(INDEX('Out_ComplianceTracker'!$W$8:$W$307,MATCH(10,'Out_ComplianceTracker'!$Z$8:$Z$307,0)),"") | E30: =IFERROR(INDEX('Out_ComplianceTracker'!$R$8:$R$307,MATCH(10,'Out_ComplianceTracker'!$Z$8:$Z$307,0)),"")
A31: =IFERROR(INDEX('Out_ComplianceTracker'!$A$8:$A$307,MATCH(11,'Out_ComplianceTracker'!$Z$8:$Z$307,0)),"") | B31: =IFERROR(INDEX('Ref_Crosswalk'!$B$2:$B$500,MATCH(INDEX('Out_ComplianceTracker'!$A$8:$A$307,MATCH(11,'Out_ComplianceTracker'!$Z$8:$Z$307,0)),'Ref_Crosswalk'!$A$2:$A$500,0)),"") | C31: =IFERROR(INDEX('Out_ComplianceTracker'!$X$8:$X$307,MATCH(11,'Out_ComplianceTracker'!$Z$8:$Z$307,0)),"") | D31: =IFERROR(INDEX('Out_ComplianceTracker'!$W$8:$W$307,MATCH(11,'Out_ComplianceTracker'!$Z$8:$Z$307,0)),"") | E31: =IFERROR(INDEX('Out_ComplianceTracker'!$R$8:$R$307,MATCH(11,'Out_ComplianceTracker'!$Z$8:$Z$307,0)),"")
A32: =IFERROR(INDEX('Out_ComplianceTracker'!$A$8:$A$307,MATCH(12,'Out_ComplianceTracker'!$Z$8:$Z$307,0)),"") | B32: =IFERROR(INDEX('Ref_Crosswalk'!$B$2:$B$500,MATCH(INDEX('Out_ComplianceTracker'!$A$8:$A$307,MATCH(12,'Out_ComplianceTracker'!$Z$8:$Z$307,0)),'Ref_Crosswalk'!$A$2:$A$500,0)),"") | C32: =IFERROR(INDEX('Out_ComplianceTracker'!$X$8:$X$307,MATCH(12,'Out_ComplianceTracker'!$Z$8:$Z$307,0)),"") | D32: =IFERROR(INDEX('Out_ComplianceTracker'!$W$8:$W$307,MATCH(12,'Out_ComplianceTracker'!$Z$8:$Z$307,0)),"") | E32: =IFERROR(INDEX('Out_ComplianceTracker'!$R$8:$R$307,MATCH(12,'Out_ComplianceTracker'!$Z$8:$Z$307,0)),"")
A34: DATA INTEGRITY
A35: Provenance completeness: | D35: ="no data (Stage 2)"
A36: Traceability: | D36: ="no data (Stage 2)"
A37: Sources ingested: | D37: ="no data (Stage 2)"
A39: ACTIONS OVERDUE | G39: overdue count ► | H39: =SUMPRODUCT(('Out_ComplianceTracker'!$T$8:$T$307<>"")*('Out_ComplianceTracker'!$Y$8:$Y$307=1))
A40: DFAC_ID | B40: PERIOD_KEY | C40: WHAT'S OVERDUE
A41: =IF($H$39=0,"No overdue actions.",IFERROR(INDEX('Out_ComplianceTracker'!$A$8:$A$307,MATCH(1,'Out_ComplianceTracker'!$AA$8:$AA$307,0)),"")) | B41: =IFERROR(INDEX('Out_ComplianceTracker'!$B$8:$B$307,MATCH(1,'Out_ComplianceTracker'!$AA$8:$AA$307,0)),"") | C41: =IFERROR(INDEX('Out_ComplianceTracker'!$T$8:$T$307,MATCH(1,'Out_ComplianceTracker'!$AA$8:$AA$307,0)),"")
A42: =IFERROR(INDEX('Out_ComplianceTracker'!$A$8:$A$307,MATCH(2,'Out_ComplianceTracker'!$AA$8:$AA$307,0)),"") | B42: =IFERROR(INDEX('Out_ComplianceTracker'!$B$8:$B$307,MATCH(2,'Out_ComplianceTracker'!$AA$8:$AA$307,0)),"") | C42: =IFERROR(INDEX('Out_ComplianceTracker'!$T$8:$T$307,MATCH(2,'Out_ComplianceTracker'!$AA$8:$AA$307,0)),"")
A43: =IFERROR(INDEX('Out_ComplianceTracker'!$A$8:$A$307,MATCH(3,'Out_ComplianceTracker'!$AA$8:$AA$307,0)),"") | B43: =IFERROR(INDEX('Out_ComplianceTracker'!$B$8:$B$307,MATCH(3,'Out_ComplianceTracker'!$AA$8:$AA$307,0)),"") | C43: =IFERROR(INDEX('Out_ComplianceTracker'!$T$8:$T$307,MATCH(3,'Out_ComplianceTracker'!$AA$8:$AA$307,0)),"")
A44: =IFERROR(INDEX('Out_ComplianceTracker'!$A$8:$A$307,MATCH(4,'Out_ComplianceTracker'!$AA$8:$AA$307,0)),"") | B44: =IFERROR(INDEX('Out_ComplianceTracker'!$B$8:$B$307,MATCH(4,'Out_ComplianceTracker'!$AA$8:$AA$307,0)),"") | C44: =IFERROR(INDEX('Out_ComplianceTracker'!$T$8:$T$307,MATCH(4,'Out_ComplianceTracker'!$AA$8:$AA$307,0)),"")
A45: =IFERROR(INDEX('Out_ComplianceTracker'!$A$8:$A$307,MATCH(5,'Out_ComplianceTracker'!$AA$8:$AA$307,0)),"") | B45: =IFERROR(INDEX('Out_ComplianceTracker'!$B$8:$B$307,MATCH(5,'Out_ComplianceTracker'!$AA$8:$AA$307,0)),"") | C45: =IFERROR(INDEX('Out_ComplianceTracker'!$T$8:$T$307,MATCH(5,'Out_ComplianceTracker'!$AA$8:$AA$307,0)),"")
A46: =IFERROR(INDEX('Out_ComplianceTracker'!$A$8:$A$307,MATCH(6,'Out_ComplianceTracker'!$AA$8:$AA$307,0)),"") | B46: =IFERROR(INDEX('Out_ComplianceTracker'!$B$8:$B$307,MATCH(6,'Out_ComplianceTracker'!$AA$8:$AA$307,0)),"") | C46: =IFERROR(INDEX('Out_ComplianceTracker'!$T$8:$T$307,MATCH(6,'Out_ComplianceTracker'!$AA$8:$AA$307,0)),"")
...

Sheet Out_DataDictionary
A1: DATA DICTIONARY
A2: Every column: type, source, definition, validation, owner.
A3: TAB | B3: COLUMN | C3: TYPE | D3: SOURCE | E3: DEFINITION | F3: VALIDATION | G3: OWNER
A4: Ref_Tolerance | B4: FACILITY_TYPE | C4: Text | D4: Seed | E4: Join key to Ref_Crosswalk | F4: Unique | G4: AFSVC/VMF
A5: Ref_Tolerance | B5: TOLERANCE_PCT | C5: Number | D5: DAFMAN 34-131 | E5: Gain/loss tolerance as a fraction (0.03 = 3%) | F5: Regulatory — do not edit | G5: AFSVC/VMF
A6: Ref_Tolerance | B6: BASIS | C6: Text | D6: DAFMAN 34-131 | E6: Income basis the tolerance applies against | F6: Enum | G6: AFSVC/VMF
A7: Ref_Tolerance | B7: METRIC_TYPE | C7: Text | D7: DAFMAN 34-131 | E7: VARIANCE or MARGIN; Food 2.0 is MARGIN | F7: VARIANCE/MARGIN | G7: AFSVC/VMF
A8: Ref_Tolerance | B8: DAFMAN_CITE | C8: Text | D8: DAFMAN 34-131 | E8: Paragraph the standard comes from | F8: - | G8: AFSVC/VMF
A9: Ref_Tolerance | B9: TIER | C9: Text | D9: DAFMAN 34-131 | E9: Waiver tier (e.g. T-2) | F9: - | G9: AFSVC/VMF
A10: Ref_Tolerance | B10: NOTES | C10: Text | D10: Analyst | E10: Surfaces the 3% vs 5% conflict and the Food 2.0 gap | F10: - | G10: AFSVC/VMF
A11: Ref_Calendar | B11: PERIOD_KEY | C11: Text | D11: Derived | E11: FY{n}-P{MM}{A|B}; A=1-15, B=16-EOM | F11: Unique | G11: AFSVC/VMF
A12: Ref_Calendar | B12: FY | C12: Number | D12: Derived | E12: Federal fiscal year (Oct-Sep) | F12: - | G12: AFSVC/VMF
A13: Ref_Calendar | B13: MONTH | C13: Number | D13: Derived | E13: Calendar month number | F13: 1-12 | G13: AFSVC/VMF
A14: Ref_Calendar | B14: HALF | C14: Text | D14: Derived | E14: A (1-15) or B (16-EOM) | F14: A/B | G14: AFSVC/VMF
... A45: Out_ValidationRegister | B45: Rule results | C45: Formula | D45: Workbook | E45: PASS/FAIL/N-A per validation rule | F45: - | G45: System

Sheet Out_ValidationRegister
A1: VALIDATION REGISTER
A2: Numbered rules with live PASS/FAIL. Ledger/provenance rules activate in Stage 2+.
A3: # | B3: RULE | C3: SCOPE | D3: RESULT | E3: DETAIL
A4: 1 | B4: All DFAC_ID in the tracker resolve in Ref_Crosswalk | C4: LIVE | D4: =IF(SUMPRODUCT(('Out_ComplianceTracker'!$A$8:$A$307<>"")*('Out_ComplianceTracker'!$J$8:$J$307="UNKNOWN"))=0,"PASS","FAIL") | E4: No FACILITY_TYPE lookups return UNKNOWN.
A5: 2 | B5: Provenance completeness = 100% | C5: STAGE 2+ | D5: N/A — Stage 2+ | E5: Activates with Ledger_ProvenanceCheck.
A6: 3 | B6: All ADAPTER_VER present in Ref_AdapterManifest as ACTIVE | C6: STAGE 2+ | D6: N/A — Stage 2+ | E6: Activates with adapters.
A7: 4 | B7: No PERIOD_KEY outside Ref_Calendar | C7: LIVE | D7: =IF(SUMPRODUCT(('Out_ComplianceTracker'!$B$8:$B$307<>"")*(COUNTIF('Ref_Calendar'!$A$2:$A$500,'Out_ComplianceTracker'!$B$8:$B$307)=0))=0,"PASS","FAIL") | E7: Every tracker PERIOD_KEY exists in the calendar.
A8: 5 | B8: Sum of adapter row counts = ledger row count | C8: STAGE 2+ | D8: N/A — Stage 2+ | E8: Activates with the ledger.
A9: 6 | B9: Every FACILITY_TYPE resolves in Ref_Tolerance | C9: LIVE | D9: =IF(SUMPRODUCT(('Ref_Crosswalk'!$F$2:$F$500<>"")*(COUNTIF('Ref_Tolerance'!$A$2:$A$9,'Ref_Crosswalk'!$F$2:$F$500)=0))=0,"PASS","FAIL") | E9: Catches misclassified/unknown facility types (TC-09).
A10: 7 | B10: No TOLERANCE_PCT blank where METRIC_TYPE = VARIANCE | C10: LIVE | D10: =IF(SUMPRODUCT(('Ref_Tolerance'!$D$2:$D$9="VARIANCE")*(ISNUMBER('Ref_Tolerance'!$B$2:$B$9)=FALSE))=0,"PASS","FAIL") | E10: Every variance rule carries a numeric tolerance.
A11: 8 | B11: Streak counter resets on PASS | C11: LIVE | D11: =IF(SUMPRODUCT(('Out_ComplianceTracker'!$P$8:$P$307="PASS")*('Out_ComplianceTracker'!$O$8:$O$307<>0))=0,"PASS","FAIL") | E11: STREAK = 0 on every PASS row (TC-06).
A12: 9 | B12: Escalation state consistent with streak value | C12: LIVE | D12: =IF(SUMPRODUCT(('Out_ComplianceTracker'!$A$8:$A$307<>"")*((('Out_ComplianceTracker'!$O$8:$O$307=0)*('Out_ComplianceTracker'!$R$8:$R$307<>"CLEAR"))+(('Out_ComplianceTracker'!$O$8:$O$307=1)*('Out_ComplianceTracker'!$R$8:$R$307<>"MFR DUE - MANAGER"))+(('Out_ComplianceTracker'!$O$8:$O$307=2)*('Out_ComplianceTracker'!$R$8:$R$307<>"MFR DUE - FSS/CC SIGNATURE REQUIRED"))+(('Out_ComplianceTracker'!$O$8:$O$307>=3)*('Out_ComplianceTracker'!$R$8:$R$307<>"INVESTIGATION + REPORT OF SURVEY; MSG/CC NOTIFIED"))))=0,"PASS","FAIL") | E12: Recomputed ladder text matches ESCALATION.
A13: 10 | B13: No naked formula errors anywhere | C13: LIVE | D13: =IF(SUMPRODUCT(--ISERROR('Out_ComplianceTracker'!$J$8:$AA$307))+SUMPRODUCT(--ISERROR('Out_Dashboard'!$A$10:$E$52))=0,"PASS","FAIL") | E13: No error cells in tracker calc range or dashboard (TC-22).
A14: 11 | B14: Inventory count dates align to 15th / EOM | C14: LIVE | D14: =IF(SUMPRODUCT(('Ref_Calendar'!$A$2:$A$500<>"")*((('Ref_Calendar'!$D$2:$D$500="A")*(DAY('Ref_Calendar'!$G$2:$G$500)<>15))+(('Ref_Calendar'!$D$2:$D$500="B")*('Ref_Calendar'!$G$2:$G$500<>'Ref_Calendar'!$F$2:$F$500))))=0,"PASS","FAIL") | E14: Calendar INVENTORY_DUE matches para 7.13.
A15: 12 | B15: AMOUNT = QTY x UNIT_COST within tolerance | C15: STAGE 2+ | D15: N/A — Stage 2+ | E15: Activates with the ledger.
A16: 13 | B16: No duplicate TXN_ID | C16: STAGE 2+ | D16: N/A — Stage 2+ | E16: Activates with the ledger.
A17: 14 | B17: All EXC_CODE resolve in Ref_ExceptionTypes | C17: STAGE 2+ | D17: N/A — Stage 2+ | E17: Activates with the reconciliation layer.
B19: Live rules passing: | D19: =" "&SUMPRODUCT(--($D$4:$D$17="PASS"))&" of "&SUMPRODUCT(--($C$4:$C$17="LIVE"))
